<?xml version="1.0" ?>
<!-- =================================================================================== -->
<!-- |    This document was autogenerated by xacro from robot.xacro                    | -->
<!-- |    EDITING THIS FILE BY HAND IS NOT RECOMMENDED                                 | -->
<!-- =================================================================================== -->
<robot name="go2">
  <material name="black">
    <color rgba="0.0 0.0 0.0 1.0"/>
  </material>
  <material name="blue">
    <color rgba="0.0 0.0 0.8 1.0"/>
  </material>
  <material name="green">
    <color rgba="0.0 0.8 0.0 1.0"/>
  </material>
  <material name="grey">
    <color rgba="0.2 0.2 0.2 0.0"/>
  </material>
  <material name="silver">
    <color rgba="0.9137254901960784 0.9137254901960784 0.8470588235294118 1.0"/>
  </material>
  <material name="orange">
    <color rgba="1.0 0.4235294117647059 0.0392156862745098 1.0"/>
  </material>
  <material name="brown">
    <color rgba="0.8705882352941177 0.8117647058823529 0.7647058823529411 1.0"/>
  </material>
  <material name="red">
    <color rgba="0.8 0.0 0.0 1.0"/>
  </material>
  <material name="white">
    <color rgba="1.0 1.0 1.0 1.0"/>
  </material>
  <!-- ros_control plugin -->
    <gazebo>
    <plugin filename="liblegged_hw_sim.so" name="gazebo_ros_control">
      <robotNamespace>/</robotNamespace>
      <robotParam>legged_robot_description</robotParam>
      <robotSimType>legged_gazebo/LeggedHWSim</robotSimType>
    </plugin>
  </gazebo>
  <gazebo>
    <plugin filename="libgazebo_ros_p3d.so" name="p3d_base_controller">
      <alwaysOn>true</alwaysOn>
      <updateRate>1000.0</updateRate>
      <bodyName>base</bodyName>
      <topicName>ground_truth/state</topicName>
      <gaussianNoise>0</gaussianNoise>
      <frameName>world</frameName>
      <xyzOffsets>0 0 0</xyzOffsets>
      <rpyOffsets>0 0 0</rpyOffsets>
    </plugin>
  </gazebo>

  <gazebo reference="trunk">
    <mu1>0.2</mu1>
    <mu2>0.2</mu2>
    <kp value="1000000.0"/>
    <kd value="1.0"/>
  </gazebo>
  <gazebo reference="stick_link">
    <mu1>0.2</mu1>
    <mu2>0.2</mu2>
  </gazebo>
  <gazebo reference="base_imu">
    <mu1>0.2</mu1>
    <mu2>0.2</mu2>
  </gazebo>
  <!-- FL leg -->
  <gazebo reference="LF_hip">
    <mu1>0.2</mu1>
    <mu2>0.2</mu2>
  </gazebo>
  <gazebo reference="LF_thigh">
    <mu1>0.2</mu1>
    <mu2>0.2</mu2>
    <self_collide>1</self_collide>
    <kp value="1000000.0"/>
    <kd value="1.0"/>
  </gazebo>
  <gazebo reference="LF_calf">
    <mu1>0.2</mu1>
    <mu2>0.2</mu2>
    <self_collide>1</self_collide>
  </gazebo>
  <gazebo reference="LF_FOOT">
    <mu1>0.6</mu1>
    <mu2>0.6</mu2>
    <self_collide>1</self_collide>
    <kp value="1000000.0"/>
    <kd value="1.0"/>
  </gazebo>
  <!-- FR leg -->
  <gazebo reference="RF_hip">
    <mu1>0.2</mu1>
    <mu2>0.2</mu2>
  </gazebo>
  <gazebo reference="RF_thigh">
    <mu1>0.2</mu1>
    <mu2>0.2</mu2>
    <self_collide>1</self_collide>
    <kp value="1000000.0"/>
    <kd value="1.0"/>
  </gazebo>
  <gazebo reference="RF_calf">
    <mu1>0.2</mu1>
    <mu2>0.2</mu2>
    <self_collide>1</self_collide>
  </gazebo>
  <gazebo reference="RF_FOOT">
    <mu1>0.6</mu1>
    <mu2>0.6</mu2>
    <self_collide>1</self_collide>
    <kp value="1000000.0"/>
    <kd value="1.0"/>
  </gazebo>
  <!-- RL leg -->
  <gazebo reference="LH_hip">
    <mu1>0.2</mu1>
    <mu2>0.2</mu2>
  </gazebo>
  <gazebo reference="LH_thigh">
    <mu1>0.2</mu1>
    <mu2>0.2</mu2>
    <self_collide>1</self_collide>
    <kp value="1000000.0"/>
    <kd value="1.0"/>
  </gazebo>
  <gazebo reference="LH_calf">
    <mu1>0.2</mu1>
    <mu2>0.2</mu2>
    <self_collide>1</self_collide>
  </gazebo>
  <gazebo reference="LH_FOOT">
    <mu1>0.6</mu1>
    <mu2>0.6</mu2>
    <self_collide>1</self_collide>
    <kp value="1000000.0"/>
    <kd value="1.0"/>
  </gazebo>
  <!-- RR leg -->
  <gazebo reference="LH_hip">
    <mu1>0.2</mu1>
    <mu2>0.2</mu2>
  </gazebo>
  <gazebo reference="RH_thigh">
    <mu1>0.2</mu1>
    <mu2>0.2</mu2>
    <self_collide>1</self_collide>
    <kp value="1000000.0"/>
    <kd value="1.0"/>
  </gazebo>
  <gazebo reference="RH_calf">
    <mu1>0.2</mu1>
    <mu2>0.2</mu2>
    <self_collide>1</self_collide>
  </gazebo>
  <gazebo reference="RH_FOOT">
    <mu1>0.6</mu1>
    <mu2>0.6</mu2>
    <self_collide>1</self_collide>
    <kp value="1000000.0"/>
    <kd value="1.0"/>
  </gazebo>
  <!-- <xacro:include filename="$(find go2_gazebo)/launch/stairs.urdf.xacro"/> -->
  <!-- <xacro:stairs stairs="15" xpos="0" ypos="0" zpos="0" /> -->
  <!-- Rotor related joint and link is only for demonstrate location. -->
  <!-- Actually, the rotor will rotate and the joint is not fixed. Reduction ratio should be considered. -->
  <link name="base">
    <visual>
      <origin rpy="0 0 0" xyz="0 0 0"/>
      <geometry>
        <box size="0.001 0.001 0.001"/>
      </geometry>
    </visual>
  </link>
  <joint name="floating_base" type="fixed">
    <origin rpy="0 0 0" xyz="0 0 0"/>
    <parent link="base"/>
    <child link="trunk"/>
  </joint>
  <link name="trunk">
    <visual>
      <origin rpy="0 0 0" xyz="0 0 0"/>
      <geometry>
        <mesh filename="go2_mesh/base.dae" scale="1 1 1"/>
      </geometry>
      <!-- <material name="orange"/> -->
    </visual>
    <collision>
      <origin rpy="0 0 0" xyz="0 0 0"/>
      <geometry>
        <box size="0.3762 0.0935 0.114"/>
      </geometry>
    </collision>
    <inertial>
      <origin rpy="0 0 0" xyz="0.021112 0.0 -0.005366"/>
      <mass value="6.921"/>
      <inertia ixx="0.02448" ixy="0.00012166" ixz="0.0014849" iyy="0.098077" iyz="-3.12e-05" izz="0.107"/>
    </inertial>
  </link>
  <joint name="base_imu_joint" type="fixed">
    <parent link="trunk"/>
    <child link="base_imu"/>
    <origin rpy="0 0 0" xyz="0 0 0"/>
  </joint>

  <gazebo reference="base_imu_joint">
    <disableFixedJointLumping>true</disableFixedJointLumping>
  </gazebo>

  <link name="base_imu">
    <inertial>
      <mass value="0.001"/>
      <origin rpy="0 0 0" xyz="0 0 0"/>
      <inertia ixx="0.0001" ixy="0" ixz="0" iyy="0.0001" iyz="0" izz="0.0001"/>
    </inertial>
    <visual>
      <origin rpy="0 0 0" xyz="0 0 0"/>
      <geometry>
        <box size="0.001 0.001 0.001"/>
      </geometry>
      <!-- <material name="red"/> -->
    </visual>
    <collision>
      <origin rpy="0 0 0" xyz="0 0 0"/>
      <geometry>
        <box size=".001 .001 .001"/>
      </geometry>
    </collision>
  </link>
  <joint name="front_camera_joint" type="fixed">
    <parent link="trunk"/>
    <child link="front_camera"/>
    <origin rpy="0 0 0" xyz="0.32715 -0.00003 0.04297"/>
  </joint>
  <link name="front_camera">
    </link>
  <joint name="RF_HAA" type="revolute">
    <origin rpy="0 0 0" xyz="0.1934 -0.0465 0"/>
    <parent link="trunk"/>
    <child link="RF_hip"/>
    <axis xyz="1 0 0"/>
    <dynamics damping="0.0" friction="0.0"/>
    <limit effort="23.7" lower="-1.0472" upper="1.0472" velocity="30.1"/>
  </joint>
  <joint name="RF_hip_rotor_joint" type="fixed">
    <origin rpy="0 0 0" xyz="0.11215 -0.04675 0"/>
    <parent link="trunk"/>
    <child link="RF_hip_rotor"/>
  </joint>
  <link name="RF_hip">
    <visual>
      <origin rpy="3.141592653589793 0 0" xyz="0 0 0"/>
      <geometry>
        <mesh filename="go2_mesh/hip.dae" scale="1 1 1"/>
      </geometry>
      <!-- <material name="orange"/> -->
    </visual>
    <collision>
      <origin rpy="1.5707963267948966 0 0" xyz="0 -0.0955 0"/>
      <geometry>
        <cylinder length="0.04" radius="0.046"/>
      </geometry>
    </collision>
    <inertial>
      <origin rpy="0 0 0" xyz="-0.0054 -0.00194 -0.000105"/>
      <mass value="0.678"/>
      <inertia ixx="0.00048" ixy="3.01e-06" ixz="1.11e-06" iyy="0.000884" iyz="1.42e-06" izz="0.000596"/>
    </inertial>
  </link>
  <link name="RF_hip_rotor">
    <visual>
      <origin rpy="0 1.5707963267948966 0" xyz="0 0 0"/>
      <geometry>
        <cylinder length="0.02" radius="0.035"/>
      </geometry>
      <material name="green"/>
    </visual>
    <!-- <collision>
                <origin rpy="0 ${PI/2.0} 0" xyz="0 0 0"/>
                <geometry>
                    <cylinder length="0.02" radius="0.035"/>
                </geometry>
            </collision> -->
    <inertial>
      <origin rpy="0 0 0" xyz="0.0 0.0 0.0"/>
      <mass value="0.089"/>
      <inertia ixx="0.000111842" ixy="0.0" ixz="0.0" iyy="5.9647e-05" iyz="0.0" izz="5.9647e-05"/>
    </inertial>
  </link>
  <joint name="RF_HFE" type="revolute">
    <origin rpy="0 0 0" xyz="0 -0.0955 0"/>
    <parent link="RF_hip"/>
    <child link="RF_thigh"/>
    <axis xyz="0 1 0"/>
    <dynamics damping="0.0" friction="0.0"/>
    <limit effort="23.7" lower="-1.5708" upper="3.4907" velocity="30.1"/>
  </joint>
  <joint name="RF_thigh_rotor_joint" type="fixed">
    <origin rpy="0 0 0" xyz="0.0 0.00015 0"/>
    <parent link="RF_hip"/>
    <child link="RF_thigh_rotor"/>
  </joint>
  <link name="RF_thigh">
    <visual>
      <origin rpy="0 0 0" xyz="0 0 0"/>
      <geometry>
        <mesh filename="go2_mesh/thigh_mirror.dae" scale="1 1 1"/>
      </geometry>
      <!-- <material name="orange"/> -->
    </visual>
    <collision>
      <origin rpy="0 1.5707963267948966 0" xyz="0 0 -0.1065"/>
      <geometry>
        <box size="0.213 0.0245 0.034"/>
      </geometry>
    </collision>
    <inertial>
      <origin rpy="0 0 0" xyz="-0.00374 0.0223 -0.0327"/>
      <mass value="1.152"/>
      <inertia ixx="0.00584" ixy="-8.72e-05" ixz="-0.000289" iyy="0.0058" iyz="-0.000808" izz="0.00103"/>
    </inertial>
  </link>
  <link name="RF_thigh_rotor">
    <visual>
      <origin rpy="1.5707963267948966 0 0" xyz="0 0 0"/>
      <geometry>
        <cylinder length="0.02" radius="0.035"/>
      </geometry>
      <material name="green"/>
    </visual>
    <!-- <collision>
                <origin rpy="${PI/2.0} 0 0" xyz="0 0 0"/>
                <geometry>
                    <cylinder length="0.02" radius="0.035"/>
                </geometry>
            </collision> -->
    <inertial>
      <origin rpy="0 0 0" xyz="0.0 0.0 0.0"/>
      <mass value="0.089"/>
      <inertia ixx="5.9647e-05" ixy="0.0" ixz="0.0" iyy="0.000111842" iyz="0.0" izz="5.9647e-05"/>
    </inertial>
  </link>
  <joint name="RF_KFE" type="revolute">
    <origin rpy="0 0 0" xyz="0 0 -0.213"/>
    <parent link="RF_thigh"/>
    <child link="RF_calf"/>
    <axis xyz="0 1 0"/>
    <dynamics damping="0.0" friction="0.0"/>
    <limit effort="35.55" lower="-2.7227" upper="-0.83776" velocity="20.06"/>
  </joint>
  <joint name="RF_calf_rotor_joint" type="fixed">
    <origin rpy="0 0 0" xyz="0.0 0.03235 0"/>
    <parent link="RF_thigh"/>
    <child link="RF_calf_rotor"/>
  </joint>
  <link name="RF_calf">
    <visual>
      <origin rpy="0 0 0" xyz="0 0 0"/>
      <geometry>
        <mesh filename="go2_mesh/calf.dae" scale="1 1 1"/>
      </geometry>
      <!-- <material name="orange"/> -->
    </visual>
    <collision>
      <origin rpy="0 1.5707963267948966 0" xyz="0 0 -0.1065"/>
      <geometry>
        <box size="0.213 0.016 0.016"/>
      </geometry>
    </collision>
    <inertial>
      <origin rpy="0 0 0" xyz="0.00548 -0.000975 -0.115"/>
      <mass value="0.154"/>
      <inertia ixx="0.00108" ixy="3.4e-07" ixz="1.72e-05" iyy="0.0011" iyz="8.28e-06" izz="3.29e-05"/>
    </inertial>
  </link>
  <link name="RF_calf_rotor">
    <visual>
      <origin rpy="1.5707963267948966 0 0" xyz="0 0 0"/>
      <geometry>
        <cylinder length="0.02" radius="0.035"/>
      </geometry>
      <material name="green"/>
    </visual>
    <!-- <collision>
                <origin rpy="${PI/2.0} 0 0" xyz="0 0 0"/>
                <geometry>
                    <cylinder length="0.02" radius="0.035"/>
                </geometry>
            </collision> -->
    <inertial>
      <origin rpy="0 0 0" xyz="0.0 0.0 0.0"/>
      <mass value="0.089"/>
      <inertia ixx="5.9647e-05" ixy="0.0" ixz="0.0" iyy="0.000111842" iyz="0.0" izz="5.9647e-05"/>
    </inertial>
  </link>
  <joint dont_collapse="true" name="RF_foot_fixed" type="fixed">
    <origin rpy="0 0 0" xyz="0 0 -0.213"/>
    <parent link="RF_calf"/>
    <child link="RF_FOOT"/>
  </joint>

  <gazebo reference="RF_foot_fixed">
    <disableFixedJointLumping>true</disableFixedJointLumping>
  </gazebo>

  <link name="RF_FOOT">
    <visual>
      <origin rpy="0 0 0" xyz="0 0 0"/>
      <geometry>
        <sphere radius="0.01"/>
      </geometry>
      <!-- <material name="orange"/> -->
    </visual>
    <collision>
      <origin rpy="0 0 0" xyz="0 0 0"/>
      <geometry>
        <sphere radius="0.02"/>
      </geometry>
    </collision>
    <inertial>
      <mass value="0.06"/>
      <inertia ixx="9.600000000000001e-06" ixy="0.0" ixz="0.0" iyy="9.600000000000001e-06" iyz="0.0" izz="9.600000000000001e-06"/>
    </inertial>
  </link>
  <transmission name="RF_hip_tran">
    <type>transmission_interface/SimpleTransmission</type>
    <joint name="RF_HAA">
      <hardwareInterface>hardware_interface/EffortJointInterface</hardwareInterface>
    </joint>
    <actuator name="RF_hip_motor">
      <hardwareInterface>hardware_interface/EffortJointInterface</hardwareInterface>
      <mechanicalReduction>1</mechanicalReduction>
    </actuator>
  </transmission>
  <transmission name="RF_thigh_tran">
    <type>transmission_interface/SimpleTransmission</type>
    <joint name="RF_HFE">
      <hardwareInterface>hardware_interface/EffortJointInterface</hardwareInterface>
    </joint>
    <actuator name="RF_thigh_motor">
      <hardwareInterface>hardware_interface/EffortJointInterface</hardwareInterface>
      <mechanicalReduction>1</mechanicalReduction>
    </actuator>
  </transmission>
  <transmission name="RF_calf_tran">
    <type>transmission_interface/SimpleTransmission</type>
    <joint name="RF_KFE">
      <hardwareInterface>hardware_interface/EffortJointInterface</hardwareInterface>
    </joint>
    <actuator name="RF_calf_motor">
      <hardwareInterface>hardware_interface/EffortJointInterface</hardwareInterface>
      <mechanicalReduction>1</mechanicalReduction>
    </actuator>
  </transmission>
  <joint name="LF_HAA" type="revolute">
    <origin rpy="0 0 0" xyz="0.1934 0.0465 0"/>
    <parent link="trunk"/>
    <child link="LF_hip"/>
    <axis xyz="1 0 0"/>
    <dynamics damping="0.0" friction="0.0"/>
    <limit effort="23.7" lower="-1.0472" upper="1.0472" velocity="30.1"/>
  </joint>
  <joint name="LF_hip_rotor_joint" type="fixed">
    <origin rpy="0 0 0" xyz="0.11215 0.04675 0"/>
    <parent link="trunk"/>
    <child link="LF_hip_rotor"/>
  </joint>
  <link name="LF_hip">
    <visual>
      <origin rpy="0 0 0" xyz="0 0 0"/>
      <geometry>
        <mesh filename="go2_mesh/hip.dae" scale="1 1 1"/>
      </geometry>
      <!-- <material name="orange"/> -->
    </visual>
    <collision>
      <origin rpy="1.5707963267948966 0 0" xyz="0 0.0955 0"/>
      <geometry>
        <cylinder length="0.04" radius="0.046"/>
      </geometry>
    </collision>
    <inertial>
      <origin rpy="0 0 0" xyz="-0.0054 0.00194 -0.000105"/>
      <mass value="0.678"/>
      <inertia ixx="0.00048" ixy="-3.01e-06" ixz="1.11e-06" iyy="0.000884" iyz="-1.42e-06" izz="0.000596"/>
    </inertial>
  </link>
  <link name="LF_hip_rotor">
    <visual>
      <origin rpy="0 1.5707963267948966 0" xyz="0 0 0"/>
      <geometry>
        <cylinder length="0.02" radius="0.035"/>
      </geometry>
      <material name="green"/>
    </visual>
    <!-- <collision>
                <origin rpy="0 ${PI/2.0} 0" xyz="0 0 0"/>
                <geometry>
                    <cylinder length="0.02" radius="0.035"/>
                </geometry>
            </collision> -->
    <inertial>
      <origin rpy="0 0 0" xyz="0.0 0.0 0.0"/>
      <mass value="0.089"/>
      <inertia ixx="0.000111842" ixy="0.0" ixz="0.0" iyy="5.9647e-05" iyz="0.0" izz="5.9647e-05"/>
    </inertial>
  </link>
  <joint name="LF_HFE" type="revolute">
    <origin rpy="0 0 0" xyz="0 0.0955 0"/>
    <parent link="LF_hip"/>
    <child link="LF_thigh"/>
    <axis xyz="0 1 0"/>
    <dynamics damping="0.0" friction="0.0"/>
    <limit effort="23.7" lower="-1.5708" upper="3.4907" velocity="30.1"/>
  </joint>
  <joint name="LF_thigh_rotor_joint" type="fixed">
    <origin rpy="0 0 0" xyz="0.0 -0.00015 0"/>
    <parent link="LF_hip"/>
    <child link="LF_thigh_rotor"/>
  </joint>
  <link name="LF_thigh">
    <visual>
      <origin rpy="0 0 0" xyz="0 0 0"/>
      <geometry>
        <mesh filename="go2_mesh/thigh.dae" scale="1 1 1"/>
      </geometry>
      <!-- <material name="orange"/> -->
    </visual>
    <collision>
      <origin rpy="0 1.5707963267948966 0" xyz="0 0 -0.1065"/>
      <geometry>
        <box size="0.213 0.0245 0.034"/>
      </geometry>
    </collision>
    <inertial>
      <origin rpy="0 0 0" xyz="-0.00374 -0.0223 -0.0327"/>
      <mass value="1.152"/>
      <inertia ixx="0.00584" ixy="8.72e-05" ixz="-0.000289" iyy="0.0058" iyz="0.000808" izz="0.00103"/>
    </inertial>
  </link>
  <link name="LF_thigh_rotor">
    <visual>
      <origin rpy="1.5707963267948966 0 0" xyz="0 0 0"/>
      <geometry>
        <cylinder length="0.02" radius="0.035"/>
      </geometry>
      <material name="green"/>
    </visual>
    <!-- <collision>
                <origin rpy="${PI/2.0} 0 0" xyz="0 0 0"/>
                <geometry>
                    <cylinder length="0.02" radius="0.035"/>
                </geometry>
            </collision> -->
    <inertial>
      <origin rpy="0 0 0" xyz="0.0 0.0 0.0"/>
      <mass value="0.089"/>
      <inertia ixx="5.9647e-05" ixy="0.0" ixz="0.0" iyy="0.000111842" iyz="0.0" izz="5.9647e-05"/>
    </inertial>
  </link>
  <joint name="LF_KFE" type="revolute">
    <origin rpy="0 0 0" xyz="0 0 -0.213"/>
    <parent link="LF_thigh"/>
    <child link="LF_calf"/>
    <axis xyz="0 1 0"/>
    <dynamics damping="0.0" friction="0.0"/>
    <limit effort="35.55" lower="-2.7227" upper="-0.83776" velocity="20.06"/>
  </joint>
  <joint name="LF_calf_rotor_joint" type="fixed">
    <origin rpy="0 0 0" xyz="0.0 -0.03235 0"/>
    <parent link="LF_thigh"/>
    <child link="LF_calf_rotor"/>
  </joint>
  <link name="LF_calf">
    <visual>
      <origin rpy="0 0 0" xyz="0 0 0"/>
      <geometry>
        <mesh filename="go2_mesh/calf.dae" scale="1 1 1"/>
      </geometry>
      <!-- <material name="orange"/> -->
    </visual>
    <collision>
      <origin rpy="0 1.5707963267948966 0" xyz="0 0 -0.1065"/>
      <geometry>
        <box size="0.213 0.016 0.016"/>
      </geometry>
    </collision>
    <inertial>
      <origin rpy="0 0 0" xyz="0.00548 -0.000975 -0.115"/>
      <mass value="0.154"/>
      <inertia ixx="0.00108" ixy="3.4e-07" ixz="1.72e-05" iyy="0.0011" iyz="8.28e-06" izz="3.29e-05"/>
    </inertial>
  </link>
  <link name="LF_calf_rotor">
    <visual>
      <origin rpy="1.5707963267948966 0 0" xyz="0 0 0"/>
      <geometry>
        <cylinder length="0.02" radius="0.035"/>
      </geometry>
      <material name="green"/>
    </visual>
    <!-- <collision>
                <origin rpy="${PI/2.0} 0 0" xyz="0 0 0"/>
                <geometry>
                    <cylinder length="0.02" radius="0.035"/>
                </geometry>
            </collision> -->
    <inertial>
      <origin rpy="0 0 0" xyz="0.0 0.0 0.0"/>
      <mass value="0.089"/>
      <inertia ixx="5.9647e-05" ixy="0.0" ixz="0.0" iyy="0.000111842" iyz="0.0" izz="5.9647e-05"/>
    </inertial>
  </link>
  <joint dont_collapse="true" name="LF_foot_fixed" type="fixed">
    <origin rpy="0 0 0" xyz="0 0 -0.213"/>
    <parent link="LF_calf"/>
    <child link="LF_FOOT"/>
  </joint>

  <gazebo reference="LF_foot_fixed">
    <disableFixedJointLumping>true</disableFixedJointLumping>
  </gazebo>

  <link name="LF_FOOT">
    <visual>
      <origin rpy="0 0 0" xyz="0 0 0"/>
      <geometry>
        <sphere radius="0.01"/>
      </geometry>
      <!-- <material name="orange"/> -->
    </visual>
    <collision>
      <origin rpy="0 0 0" xyz="0 0 0"/>
      <geometry>
        <sphere radius="0.02"/>
      </geometry>
    </collision>
    <inertial>
      <mass value="0.06"/>
      <inertia ixx="9.600000000000001e-06" ixy="0.0" ixz="0.0" iyy="9.600000000000001e-06" iyz="0.0" izz="9.600000000000001e-06"/>
    </inertial>
  </link>
  <transmission name="LF_hip_tran">
    <type>transmission_interface/SimpleTransmission</type>
    <joint name="LF_HAA">
      <hardwareInterface>hardware_interface/EffortJointInterface</hardwareInterface>
    </joint>
    <actuator name="LF_hip_motor">
      <hardwareInterface>hardware_interface/EffortJointInterface</hardwareInterface>
      <mechanicalReduction>1</mechanicalReduction>
    </actuator>
  </transmission>
  <transmission name="LF_thigh_tran">
    <type>transmission_interface/SimpleTransmission</type>
    <joint name="LF_HFE">
      <hardwareInterface>hardware_interface/EffortJointInterface</hardwareInterface>
    </joint>
    <actuator name="LF_thigh_motor">
      <hardwareInterface>hardware_interface/EffortJointInterface</hardwareInterface>
      <mechanicalReduction>1</mechanicalReduction>
    </actuator>
  </transmission>
  <transmission name="LF_calf_tran">
    <type>transmission_interface/SimpleTransmission</type>
    <joint name="LF_KFE">
      <hardwareInterface>hardware_interface/EffortJointInterface</hardwareInterface>
    </joint>
    <actuator name="LF_calf_motor">
      <hardwareInterface>hardware_interface/EffortJointInterface</hardwareInterface>
      <mechanicalReduction>1</mechanicalReduction>
    </actuator>
  </transmission>
  <joint name="RH_HAA" type="revolute">
    <origin rpy="0 0 0" xyz="-0.1934 -0.0465 0"/>
    <parent link="trunk"/>
    <child link="RH_hip"/>
    <axis xyz="1 0 0"/>
    <dynamics damping="0.0" friction="0.0"/>
    <limit effort="23.7" lower="-1.0472" upper="1.0472" velocity="30.1"/>
  </joint>
  <joint name="RH_hip_rotor_joint" type="fixed">
    <origin rpy="0 0 0" xyz="-0.11215 -0.04675 0"/>
    <parent link="trunk"/>
    <child link="RH_hip_rotor"/>
  </joint>
  <link name="RH_hip">
    <visual>
      <origin rpy="3.141592653589793 3.141592653589793 0" xyz="0 0 0"/>
      <geometry>
        <mesh filename="go2_mesh/hip.dae" scale="1 1 1"/>
      </geometry>
      <!-- <material name="orange"/> -->
    </visual>
    <collision>
      <origin rpy="1.5707963267948966 0 0" xyz="0 -0.0955 0"/>
      <geometry>
        <cylinder length="0.04" radius="0.046"/>
      </geometry>
    </collision>
    <inertial>
      <origin rpy="0 0 0" xyz="0.0054 -0.00194 -0.000105"/>
      <mass value="0.678"/>
      <inertia ixx="0.00048" ixy="-3.01e-06" ixz="-1.11e-06" iyy="0.000884" iyz="1.42e-06" izz="0.000596"/>
    </inertial>
  </link>
  <link name="RH_hip_rotor">
    <visual>
      <origin rpy="0 1.5707963267948966 0" xyz="0 0 0"/>
      <geometry>
        <cylinder length="0.02" radius="0.035"/>
      </geometry>
      <material name="green"/>
    </visual>
    <!-- <collision>
                <origin rpy="0 ${PI/2.0} 0" xyz="0 0 0"/>
                <geometry>
                    <cylinder length="0.02" radius="0.035"/>
                </geometry>
            </collision> -->
    <inertial>
      <origin rpy="0 0 0" xyz="0.0 0.0 0.0"/>
      <mass value="0.089"/>
      <inertia ixx="0.000111842" ixy="0.0" ixz="0.0" iyy="5.9647e-05" iyz="0.0" izz="5.9647e-05"/>
    </inertial>
  </link>
  <joint name="RH_HFE" type="revolute">
    <origin rpy="0 0 0" xyz="0 -0.0955 0"/>
    <parent link="RH_hip"/>
    <child link="RH_thigh"/>
    <axis xyz="0 1 0"/>
    <dynamics damping="0.0" friction="0.0"/>
    <limit effort="23.7" lower="-1.5708" upper="3.4907" velocity="30.1"/>
  </joint>
  <joint name="RH_thigh_rotor_joint" type="fixed">
    <origin rpy="0 0 0" xyz="0.0 0.00015 0"/>
    <parent link="RH_hip"/>
    <child link="RH_thigh_rotor"/>
  </joint>
  <link name="RH_thigh">
    <visual>
      <origin rpy="0 0 0" xyz="0 0 0"/>
      <geometry>
        <mesh filename="go2_mesh/thigh_mirror.dae" scale="1 1 1"/>
      </geometry>
      <!-- <material name="orange"/> -->
    </visual>
    <collision>
      <origin rpy="0 1.5707963267948966 0" xyz="0 0 -0.1065"/>
      <geometry>
        <box size="0.213 0.0245 0.034"/>
      </geometry>
    </collision>
    <inertial>
      <origin rpy="0 0 0" xyz="-0.00374 0.0223 -0.0327"/>
      <mass value="1.152"/>
      <inertia ixx="0.00584" ixy="-8.72e-05" ixz="-0.000289" iyy="0.0058" iyz="-0.000808" izz="0.00103"/>
    </inertial>
  </link>
  <link name="RH_thigh_rotor">
    <visual>
      <origin rpy="1.5707963267948966 0 0" xyz="0 0 0"/>
      <geometry>
        <cylinder length="0.02" radius="0.035"/>
      </geometry>
      <material name="green"/>
    </visual>
    <!-- <collision>
                <origin rpy="${PI/2.0} 0 0" xyz="0 0 0"/>
                <geometry>
                    <cylinder length="0.02" radius="0.035"/>
                </geometry>
            </collision> -->
    <inertial>
      <origin rpy="0 0 0" xyz="0.0 0.0 0.0"/>
      <mass value="0.089"/>
      <inertia ixx="5.9647e-05" ixy="0.0" ixz="0.0" iyy="0.000111842" iyz="0.0" izz="5.9647e-05"/>
    </inertial>
  </link>
  <joint name="RH_KFE" type="revolute">
    <origin rpy="0 0 0" xyz="0 0 -0.213"/>
    <parent link="RH_thigh"/>
    <child link="RH_calf"/>
    <axis xyz="0 1 0"/>
    <dynamics damping="0.0" friction="0.0"/>
    <limit effort="35.55" lower="-2.7227" upper="-0.83776" velocity="20.06"/>
  </joint>
  <joint name="RH_calf_rotor_joint" type="fixed">
    <origin rpy="0 0 0" xyz="0.0 0.03235 0"/>
    <parent link="RH_thigh"/>
    <child link="RH_calf_rotor"/>
  </joint>
  <link name="RH_calf">
    <visual>
      <origin rpy="0 0 0" xyz="0 0 0"/>
      <geometry>
        <mesh filename="go2_mesh/calf.dae" scale="1 1 1"/>
      </geometry>
      <!-- <material name="orange"/> -->
    </visual>
    <collision>
      <origin rpy="0 1.5707963267948966 0" xyz="0 0 -0.1065"/>
      <geometry>
        <box size="0.213 0.016 0.016"/>
      </geometry>
    </collision>
    <inertial>
      <origin rpy="0 0 0" xyz="0.00548 -0.000975 -0.115"/>
      <mass value="0.154"/>
      <inertia ixx="0.00108" ixy="3.4e-07" ixz="1.72e-05" iyy="0.0011" iyz="8.28e-06" izz="3.29e-05"/>
    </inertial>
  </link>
  <link name="RH_calf_rotor">
    <visual>
      <origin rpy="1.5707963267948966 0 0" xyz="0 0 0"/>
      <geometry>
        <cylinder length="0.02" radius="0.035"/>
      </geometry>
      <material name="green"/>
    </visual>
    <!-- <collision>
                <origin rpy="${PI/2.0} 0 0" xyz="0 0 0"/>
                <geometry>
                    <cylinder length="0.02" radius="0.035"/>
                </geometry>
            </collision> -->
    <inertial>
      <origin rpy="0 0 0" xyz="0.0 0.0 0.0"/>
      <mass value="0.089"/>
      <inertia ixx="5.9647e-05" ixy="0.0" ixz="0.0" iyy="0.000111842" iyz="0.0" izz="5.9647e-05"/>
    </inertial>
  </link>
  <joint dont_collapse="true" name="RH_foot_fixed" type="fixed">
    <origin rpy="0 0 0" xyz="0 0 -0.213"/>
    <parent link="RH_calf"/>
    <child link="RH_FOOT"/>
  </joint>

  <gazebo reference="RH_foot_fixed">
    <disableFixedJointLumping>true</disableFixedJointLumping>
  </gazebo>

  <link name="RH_FOOT">
    <visual>
      <origin rpy="0 0 0" xyz="0 0 0"/>
      <geometry>
        <sphere radius="0.01"/>
      </geometry>
      <!-- <material name="orange"/> -->
    </visual>
    <collision>
      <origin rpy="0 0 0" xyz="0 0 0"/>
      <geometry>
        <sphere radius="0.02"/>
      </geometry>
    </collision>
    <inertial>
      <mass value="0.06"/>
      <inertia ixx="9.600000000000001e-06" ixy="0.0" ixz="0.0" iyy="9.600000000000001e-06" iyz="0.0" izz="9.600000000000001e-06"/>
    </inertial>
  </link>
  <transmission name="RH_hip_tran">
    <type>transmission_interface/SimpleTransmission</type>
    <joint name="RH_HAA">
      <hardwareInterface>hardware_interface/EffortJointInterface</hardwareInterface>
    </joint>
    <actuator name="RH_hip_motor">
      <hardwareInterface>hardware_interface/EffortJointInterface</hardwareInterface>
      <mechanicalReduction>1</mechanicalReduction>
    </actuator>
  </transmission>
  <transmission name="RH_thigh_tran">
    <type>transmission_interface/SimpleTransmission</type>
    <joint name="RH_HFE">
      <hardwareInterface>hardware_interface/EffortJointInterface</hardwareInterface>
    </joint>
    <actuator name="RH_thigh_motor">
      <hardwareInterface>hardware_interface/EffortJointInterface</hardwareInterface>
      <mechanicalReduction>1</mechanicalReduction>
    </actuator>
  </transmission>
  <transmission name="RH_calf_tran">
    <type>transmission_interface/SimpleTransmission</type>
    <joint name="RH_KFE">
      <hardwareInterface>hardware_interface/EffortJointInterface</hardwareInterface>
    </joint>
    <actuator name="RH_calf_motor">
      <hardwareInterface>hardware_interface/EffortJointInterface</hardwareInterface>
      <mechanicalReduction>1</mechanicalReduction>
    </actuator>
  </transmission>
  <joint name="LH_HAA" type="revolute">
    <origin rpy="0 0 0" xyz="-0.1934 0.0465 0"/>
    <parent link="trunk"/>
    <child link="LH_hip"/>
    <axis xyz="1 0 0"/>
    <dynamics damping="0.0" friction="0.0"/>
    <limit effort="23.7" lower="-1.0472" upper="1.0472" velocity="30.1"/>
  </joint>
  <joint name="LH_hip_rotor_joint" type="fixed">
    <origin rpy="0 0 0" xyz="-0.11215 0.04675 0"/>
    <parent link="trunk"/>
    <child link="LH_hip_rotor"/>
  </joint>
  <link name="LH_hip">
    <visual>
      <origin rpy="0 3.141592653589793 0" xyz="0 0 0"/>
      <geometry>
        <mesh filename="go2_mesh/hip.dae" scale="1 1 1"/>
      </geometry>
      <!-- <material name="orange"/> -->
    </visual>
    <collision>
      <origin rpy="1.5707963267948966 0 0" xyz="0 0.0955 0"/>
      <geometry>
        <cylinder length="0.04" radius="0.046"/>
      </geometry>
    </collision>
    <inertial>
      <origin rpy="0 0 0" xyz="0.0054 0.00194 -0.000105"/>
      <mass value="0.678"/>
      <inertia ixx="0.00048" ixy="3.01e-06" ixz="-1.11e-06" iyy="0.000884" iyz="-1.42e-06" izz="0.000596"/>
    </inertial>
  </link>
  <link name="LH_hip_rotor">
    <visual>
      <origin rpy="0 1.5707963267948966 0" xyz="0 0 0"/>
      <geometry>
        <cylinder length="0.02" radius="0.035"/>
      </geometry>
      <material name="green"/>
    </visual>
    <!-- <collision>
                <origin rpy="0 ${PI/2.0} 0" xyz="0 0 0"/>
                <geometry>
                    <cylinder length="0.02" radius="0.035"/>
                </geometry>
            </collision> -->
    <inertial>
      <origin rpy="0 0 0" xyz="0.0 0.0 0.0"/>
      <mass value="0.089"/>
      <inertia ixx="0.000111842" ixy="0.0" ixz="0.0" iyy="5.9647e-05" iyz="0.0" izz="5.9647e-05"/>
    </inertial>
  </link>
  <joint name="LH_HFE" type="revolute">
    <origin rpy="0 0 0" xyz="0 0.0955 0"/>
    <parent link="LH_hip"/>
    <child link="LH_thigh"/>
    <axis xyz="0 1 0"/>
    <dynamics damping="0.0" friction="0.0"/>
    <limit effort="23.7" lower="-1.5708" upper="3.4907" velocity="30.1"/>
  </joint>
  <joint name="LH_thigh_rotor_joint" type="fixed">
    <origin rpy="0 0 0" xyz="0.0 -0.00015 0"/>
    <parent link="LH_hip"/>
    <child link="LH_thigh_rotor"/>
  </joint>
  <link name="LH_thigh">
    <visual>
      <origin rpy="0 0 0" xyz="0 0 0"/>
      <geometry>
        <mesh filename="go2_mesh/thigh.dae" scale="1 1 1"/>
      </geometry>
      <!-- <material name="orange"/> -->
    </visual>
    <collision>
      <origin rpy="0 1.5707963267948966 0" xyz="0 0 -0.1065"/>
      <geometry>
        <box size="0.213 0.0245 0.034"/>
      </geometry>
    </collision>
    <inertial>
      <origin rpy="0 0 0" xyz="-0.00374 -0.0223 -0.0327"/>
      <mass value="1.152"/>
      <inertia ixx="0.00584" ixy="8.72e-05" ixz="-0.000289" iyy="0.0058" iyz="0.000808" izz="0.00103"/>
    </inertial>
  </link>
  <link name="LH_thigh_rotor">
    <visual>
      <origin rpy="1.5707963267948966 0 0" xyz="0 0 0"/>
      <geometry>
        <cylinder length="0.02" radius="0.035"/>
      </geometry>
      <material name="green"/>
    </visual>
    <!-- <collision>
                <origin rpy="${PI/2.0} 0 0" xyz="0 0 0"/>
                <geometry>
                    <cylinder length="0.02" radius="0.035"/>
                </geometry>
            </collision> -->
    <inertial>
      <origin rpy="0 0 0" xyz="0.0 0.0 0.0"/>
      <mass value="0.089"/>
      <inertia ixx="5.9647e-05" ixy="0.0" ixz="0.0" iyy="0.000111842" iyz="0.0" izz="5.9647e-05"/>
    </inertial>
  </link>
  <joint name="LH_KFE" type="revolute">
    <origin rpy="0 0 0" xyz="0 0 -0.213"/>
    <parent link="LH_thigh"/>
    <child link="LH_calf"/>
    <axis xyz="0 1 0"/>
    <dynamics damping="0.0" friction="0.0"/>
    <limit effort="35.55" lower="-2.7227" upper="-0.83776" velocity="20.06"/>
  </joint>
  <joint name="LH_calf_rotor_joint" type="fixed">
    <origin rpy="0 0 0" xyz="0.0 -0.03235 0"/>
    <parent link="LH_thigh"/>
    <child link="LH_calf_rotor"/>
  </joint>
  <link name="LH_calf">
    <visual>
      <origin rpy="0 0 0" xyz="0 0 0"/>
      <geometry>
        <mesh filename="go2_mesh/calf.dae" scale="1 1 1"/>
      </geometry>
      <!-- <material name="orange"/> -->
    </visual>
    <collision>
      <origin rpy="0 1.5707963267948966 0" xyz="0 0 -0.1065"/>
      <geometry>
        <box size="0.213 0.016 0.016"/>
      </geometry>
    </collision>
    <inertial>
      <origin rpy="0 0 0" xyz="0.00548 -0.000975 -0.115"/>
      <mass value="0.154"/>
      <inertia ixx="0.00108" ixy="3.4e-07" ixz="1.72e-05" iyy="0.0011" iyz="8.28e-06" izz="3.29e-05"/>
    </inertial>
  </link>
  <link name="LH_calf_rotor">
    <visual>
      <origin rpy="1.5707963267948966 0 0" xyz="0 0 0"/>
      <geometry>
        <cylinder length="0.02" radius="0.035"/>
      </geometry>
      <material name="green"/>
    </visual>
    <!-- <collision>
                <origin rpy="${PI/2.0} 0 0" xyz="0 0 0"/>
                <geometry>
                    <cylinder length="0.02" radius="0.035"/>
                </geometry>
            </collision> -->
    <inertial>
      <origin rpy="0 0 0" xyz="0.0 0.0 0.0"/>
      <mass value="0.089"/>
      <inertia ixx="5.9647e-05" ixy="0.0" ixz="0.0" iyy="0.000111842" iyz="0.0" izz="5.9647e-05"/>
    </inertial>
  </link>
  <joint dont_collapse="true" name="LH_foot_fixed" type="fixed">
    <origin rpy="0 0 0" xyz="0 0 -0.213"/>
    <parent link="LH_calf"/>
    <child link="LH_FOOT"/>
  </joint>

  <gazebo reference="LH_foot_fixed">
    <disableFixedJointLumping>true</disableFixedJointLumping>
  </gazebo>

  <link name="LH_FOOT">
    <visual>
      <origin rpy="0 0 0" xyz="0 0 0"/>
      <geometry>
        <sphere radius="0.01"/>
      </geometry>
      <!-- <material name="orange"/> -->
    </visual>
    <collision>
      <origin rpy="0 0 0" xyz="0 0 0"/>
      <geometry>
        <sphere radius="0.02"/>
      </geometry>
    </collision>
    <inertial>
      <mass value="0.06"/>
      <inertia ixx="9.600000000000001e-06" ixy="0.0" ixz="0.0" iyy="9.600000000000001e-06" iyz="0.0" izz="9.600000000000001e-06"/>
    </inertial>
  </link>
  <transmission name="LH_hip_tran">
    <type>transmission_interface/SimpleTransmission</type>
    <joint name="LH_HAA">
      <hardwareInterface>hardware_interface/EffortJointInterface</hardwareInterface>
    </joint>
    <actuator name="LH_hip_motor">
      <hardwareInterface>hardware_interface/EffortJointInterface</hardwareInterface>
      <mechanicalReduction>1</mechanicalReduction>
    </actuator>
  </transmission>
  <transmission name="LH_thigh_tran">
    <type>transmission_interface/SimpleTransmission</type>
    <joint name="LH_HFE">
      <hardwareInterface>hardware_interface/EffortJointInterface</hardwareInterface>
    </joint>
    <actuator name="LH_thigh_motor">
      <hardwareInterface>hardware_interface/EffortJointInterface</hardwareInterface>
      <mechanicalReduction>1</mechanicalReduction>
    </actuator>
  </transmission>
  <transmission name="LH_calf_tran">
    <type>transmission_interface/SimpleTransmission</type>
    <joint name="LH_KFE">
      <hardwareInterface>hardware_interface/EffortJointInterface</hardwareInterface>
    </joint>
    <actuator name="LH_calf_motor">
      <hardwareInterface>hardware_interface/EffortJointInterface</hardwareInterface>
      <mechanicalReduction>1</mechanicalReduction>
    </actuator>
  </transmission>
</robot>
