<?xml version="1.0" encoding="utf-8"?>
<robot name="1dof">
  <material name="black">
    <color rgba="0.0 0.0 0.0 1.0"/>
  </material>
  <material name="blue">
    <color rgba="0.0 0.0 0.8 1.0"/>
  </material>
  <material name="green">
    <color rgba="0.0 0.8 0.0 1.0"/>
  </material>
  <material name="grey">
    <color rgba="0.2 0.2 0.2 1.0"/>
  </material>
  <material name="silver">
    <color rgba="0.913725490196 0.913725490196 0.847058823529 1.0"/>
  </material>
  <material name="orange">
    <color rgba="1.0 0.423529411765 0.0392156862745 1.0"/>
  </material>
  <material name="brown">
    <color rgba="0.870588235294 0.811764705882 0.764705882353 1.0"/>
  </material>
  <material name="red">
    <color rgba="0.8 0.0 0.0 1.0"/>
  </material>
  <material name="white">
    <color rgba="1.0 1.0 1.0 1.0"/>
  </material>

  <!-- <link name="world"/> -->

  <link name="trunk">
	 <inertial>
     <origin xyz="0 0 0" rpy="0 0 0"/> 
     <mass value="50"/>
     <inertia ixx="0.03"  ixy="0"  ixz="0" iyy="0.02" iyz="0" izz="0.03" />
    </inertial>
    <visual>
     <origin xyz="0 0 0" rpy="0 0 0" />
     <geometry>
       <box size="0.050 0.080 0.050"/>
     </geometry>
     <material name="blue"/>
    </visual>
    <collision>
     <origin xyz="0 0 0" rpy="0 0 0"/>
     <geometry>
       <box size="0.050 0.080 0.050"/>
     </geometry>
    </collision> 
  </link>


  <link name="link1">
	  <inertial>
     <origin xyz="0 0 0.125" rpy="0 0 0"/>
     <mass value="1"/>
     <inertia ixx="0.005"  ixy="0"  ixz="0" iyy="0.005" iyz="0" izz="0.00005" />
    </inertial>
	  <visual>
     <origin xyz="0 0 0.125" rpy="0 0 0" />
     <geometry>
       <cylinder radius="0.01" length="0.250"/>
     </geometry>
     <material name="orange"/>
    </visual>
	  <collision>
     <origin xyz="0 0 0.125" rpy="0 0 0"/>
     <geometry>
       <cylinder radius="0.01" length="0.250"/>
     </geometry>
    </collision>
  </link>

  
  <link name="link2">
	  <inertial>
     <origin xyz="0 0 0.125" rpy="0 0 0"/>
     <mass value="1"/>
     <inertia ixx="0.005"  ixy="0"  ixz="0" iyy="0.005" iyz="0" izz="0.00005" />
    </inertial>
	  <visual>
     <origin xyz="0 0 0.125" rpy="0 0 0" />
     <geometry>
       <cylinder radius="0.01" length="0.250"/>
     </geometry>
     <material name="orange"/>
    </visual>
	  <collision>
     <origin xyz="0 0 0.125" rpy="0 0 0"/>
     <geometry>
       <cylinder radius="0.01" length="0.250"/>
     </geometry>
    </collision>
  </link>


  

  <!-- Joints -->
  <!-- <joint name="Joint0" type="floating">
    <parent link="world"/>
    <child link="trunk"/>
    <axis xyz="0 0 0"/>
    <origin xyz="0 0 0.15" rpy="0 0 0" />
  </joint> -->

  <joint name="Joint1" type="revolute">
    <parent link="trunk"/>
    <child link="link1"/>
    <axis xyz="0 1 0"/>
    <origin xyz="0 0.06 0.0" rpy="0 0 0" />
  </joint>

  <joint name="Joint2" type="revolute">
    <parent link="link1"/>
    <child link="link2"/>
    <axis xyz="0 1 0"/>
    <origin xyz="0 0 0.250" rpy="0 0 0" />
  </joint>

</robot>